Workbook

Sheet Test Cases
A1: Test Case Repository – Game Store & Gifting System
A2: Prepared by: Jordan Kerry | Version: 1.0 | April 2026
A4: Test ID | B4: Module | C4: Sub-Module | D4: Test Title | E4: Preconditions | F4: Test Steps | G4: Expected Result | H4: Priority | I4: Test Type | J4: Assumed Telemetry Events | K4: Status | L4: Notes / Defect Ref
A5: Payment Methods
A6: TC-PAY-001 | B6: Payment Methods | C6: Credit/Debit Card | D6: Successful purchase with valid credit card | E6: Test account provisioned; sandbox payment gateway active; item in store | F6: 1. Navigate to store 2. Select item 3. Choose credit card payment 4. Enter valid card details 5. Confirm purchase | G6: Purchase completes successfully; item delivered; balance updated; receipt shown | H6: Critical | I6: Functional | J6: purchase_initiated, payment_authorised, purchase_completed, entitlement_granted | K6: Pass
A7: TC-PAY-002 | B7: Payment Methods | C7: Credit/Debit Card | D7: Declined credit card handling | E7: Test account provisioned; sandbox configured to decline card | F7: 1. Navigate to store 2. Select item 3. Enter card number set to decline 4. Confirm purchase | G7: Transaction declined; clear error message shown; no charge made; account balance unchanged | H7: Critical | I7: Negative | J7: purchase_initiated, payment_declined | K7: Not Run
A8: TC-PAY-003 | B8: Payment Methods | C8: Credit/Debit Card | D8: Expired card handling | E8: Test account provisioned; expired card credentials available in sandbox | F8: 1. Navigate to store 2. Select item 3. Enter expired card details 4. Attempt to confirm purchase | G8: System rejects card before processing; error message indicates card expiry; no charge | H8: High | I8: Negative | J8: purchase_initiated, payment_declined | K8: Fail
A9: TC-PAY-004 | B9: Payment Methods | C9: Credit/Debit Card | D9: Insufficient funds on debit card | E9: Sandbox card configured with balance below item price | F9: 1. Navigate to store 2. Select item priced above card balance 3. Enter card details 4. Confirm purchase | G9: Transaction declined with insufficient funds message; no charge; balance unchanged | H9: High | I9: Negative | J9: purchase_initiated, payment_declined | K9: Not Run
A10: TC-PAY-005 | B10: Payment Methods | C10: Third-Party Providers | D10: Successful purchase via PayPal | E10: PayPal sandbox account linked; item in store | F10: 1. Select item in store 2. Choose PayPal at checkout 3. Authenticate via PayPal sandbox 4. Confirm payment | G10: Payment processed; entitlement granted instantly; receipt confirmed | H10: Critical | I10: Functional | J10: purchase_initiated, payment_authorised, purchase_completed, entitlement_granted | K10: Blocked
A11: TC-PAY-006 | B11: Payment Methods | C11: Third-Party Providers | D11: Successful purchase via Alipay | E11: Alipay sandbox account configured; region-appropriate test account | F11: 1. Select item in store 2. Choose Alipay at checkout 3. Authenticate via Alipay sandbox 4. Confirm payment | G11: Payment processed; entitlement granted; receipt shown; balance updated | H11: Critical | I11: Functional | J11: purchase_initiated, payment_authorised, purchase_completed, entitlement_granted | K11: Not Run
A12: TC-PAY-007 | B12: Payment Methods | C12: Platform Stores | D12: Purchase via iOS App Store flow | E12: iOS test build installed; sandbox Apple ID provisioned | F12: 1. Open game on iOS 2. Navigate to store 3. Select item 4. Complete purchase via Apple Pay/App Store 5. Return to game | G12: iOS purchase confirmed; entitlement reflected in game client immediately | H12: High | I12: Integration | J12: purchase_completed, entitlement_granted | K12: In Progress
A13: TC-PAY-008 | B13: Payment Methods | C13: Platform Stores | D13: Purchase via Android Google Play flow | E13: Android test build installed; sandbox Google account provisioned | F13: 1. Open game on Android 2. Navigate to store 3. Select item 4. Complete purchase via Google Play 5. Return to game | G13: Google Play purchase confirmed; entitlement reflected in game client immediately | H13: High | I13: Integration | J13: purchase_completed, entitlement_granted | K13: Not Run
A14: Gifting
A15: TC-GIFT-001 | B15: Gifting | C15: Gift Purchase | D15: Send gift to eligible friend | E15: Sender and recipient are friends; recipient is eligible (no restrictions); item is giftable | F15: 1. Navigate to store 2. Select giftable item 3. Select 'Send as Gift' 4. Choose eligible friend 5. Confirm and complete payment | G15: Gift purchased successfully; payment deducted from sender; recipient notified | H15: Critical | I15: Functional | J15: purchase_initiated, payment_authorised, purchase_completed, entitlement_granted | K15: Not Run
A16: TC-GIFT-002 | B16: Gifting | C16: Gift Delivery | D16: Validate gift delivery to recipient | E16: Gift has been sent by sender (TC-GIFT-001 passed) | F16: 1. Log in as recipient 2. Check notifications/inbox 3. Accept or view gift | G16: Recipient receives pop-up or in-game notification; item appears in inventory immediately | H16: Critical | I16: Functional | J16: entitlement_granted | K16: Blocked
A17: TC-GIFT-003 | B17: Gifting | C17: Gift Receipt | D17: Validate gift receipt and inventory update | E17: Gift delivered to recipient | F17: 1. Log in as recipient 2. Navigate to inventory 3. Verify gifted item present | G17: Gifted item visible in inventory; no duplicate; item usable | H17: High | I17: Functional | J17: entitlement_granted | K17: Pass
A18: TC-GIFT-004 | B18: Gifting | C18: Cooldown / Scam Prevention | D18: Gifting cooldown enforced between new accounts | E18: Sender account is newly created (within cooldown period); target is eligible friend | F18: 1. Log in as new sender account 2. Attempt to send a gift 3. Observe system response | G18: System blocks gift with clear cooldown message; no charge made; cooldown timer shown | H18: High | I18: Negative | J18: purchase_initiated, purchase_failed | K18: Pass
A19: TC-GIFT-005 | B19: Gifting | C19: Cooldown / Scam Prevention | D19: Gift to ineligible player (not a friend) | E19: Target player is not on sender's friends list | F19: 1. Attempt to send gift 2. Search for non-friend player 3. Attempt to complete gift flow | G19: System prevents gift; error shown indicating player is not eligible to receive gifts | H19: High | I19: Negative | J19: purchase_initiated, purchase_failed | K19: Pass
A20: TC-GIFT-006 | B20: Gifting | C20: Cooldown / Scam Prevention | D20: Gift to player with regional restriction | E20: Target player is in a region where gifting is restricted | F20: 1. Attempt to send gift to player in restricted region 2. Confirm send | G20: Gift blocked; appropriate regional restriction message displayed; no charge | H20: Medium | I20: Negative | J20: purchase_initiated, purchase_failed | K20: Pass
A21: TC-GIFT-007 | B21: Gifting | C21: Refunds | D21: Gifting refund/return scenario | E21: Gift was successfully sent; refund policy applicable | F21: 1. Initiate refund request for gifted item 2. Follow refund flow 3. Confirm refund | G21: Refund processed correctly; sender balance restored; item removed from recipient inventory | H21: Medium | I21: Functional | K21: Pass
A22: Currency
A23: TC-CUR-001 | B23: Currency | C23: Bundle Purchase | D23: Purchase smallest currency bundle | E23: Test account with valid payment method; currency store accessible | F23: 1. Navigate to currency store 2. Select smallest bundle 3. Complete purchase | G23: Correct base currency amount credited; balance updated immediately | H23: Critical | I23: Functional | J23: purchase_initiated, payment_authorised, purchase_completed | K23: Pass
A24: TC-CUR-002 | B24: Currency | C24: Bundle Purchase | D24: Purchase largest currency bundle | E24: Test account with valid payment method; currency store accessible | F24: 1. Navigate to currency store 2. Select largest bundle 3. Complete purchase | G24: Correct base currency amount credited; balance updated; receipt shows correct amount | H24: Critical | I24: Functional | J24: purchase_initiated, payment_authorised, purchase_completed | K24: Pass
A25: TC-CUR-003 | B25: Currency | C25: Bonus Currency | D25: Validate bonus currency awarded on qualifying bundle | E25: Bundle with bonus offer active (e.g. 1000 + 150 bonus) | F25: 1. Navigate to currency store 2. Select bonus-eligible bundle 3. Complete purchase 4. Check balance | G25: Base amount (1000) AND bonus (150) both credited; total balance = 1150 | H25: Critical | I25: Functional | J25: purchase_completed | K25: Pass
A26: TC-CUR-004 | B26: Currency | C26: Balance Updates | D26: Balance updates correctly after purchase | E26: Test account with known starting balance; valid payment method | F26: 1. Note current balance 2. Purchase a currency bundle 3. Check new balance | G26: New balance = previous balance + purchased amount + any bonus; no delay in display | H26: Critical | I26: Functional | J26: purchase_completed | K26: Pass
A27: TC-CUR-005 | B27: Currency | C27: Balance Updates | D27: Balance displayed correctly after spending currency | E27: Test account with sufficient balance | F27: 1. Note current balance 2. Purchase item using virtual currency 3. Check updated balance | G27: Balance reduced by exact item cost; no rounding errors; UI reflects correctly | H27: High | I27: Functional | J27: purchase_completed | K27: Fail
A28: TC-CUR-006 | B28: Currency | C28: Bundle Purchase | D28: Purchase all available currency bundles across tiers | E28: Test accounts provisioned for each bundle tier | F28: 1. For each available bundle tier: purchase and validate credited amount | G28: Each bundle credits the exact advertised base + bonus amounts; no discrepancies | H28: High | I28: Functional | J28: purchase_completed | K28: In Progress
A29: Entitlements
A30: TC-ENT-001 | B30: Entitlements | C30: Single Item | D30: Purchase single cosmetic item (e.g. skin) | E30: Item available in store; test account with sufficient balance | F30: 1. Navigate to store 2. Select single item (skin) 3. Complete purchase 4. Check inventory | G30: Exactly one (1) instance of item in inventory; item usable in-game; no duplicates | H30: Critical | I30: Functional | J30: purchase_completed, entitlement_granted | K30: Blocked
A31: TC-ENT-002 | B31: Entitlements | C31: Bundle Items | D31: Purchase bundle of 7 items | E31: Bundle available in store; test account with sufficient balance | F31: 1. Navigate to store 2. Select item bundle 3. Complete purchase 4. Check inventory | G31: All 7 items granted; each item individually accessible; no items missing | H31: Critical | I31: Functional | J31: purchase_completed, entitlement_granted | K31: Fail
A32: TC-ENT-003 | B32: Entitlements | C32: Delivery Time | D32: Entitlement delivery within acceptable time threshold | E32: Test account; item for purchase; stopwatch/timestamp tool ready | F32: 1. Initiate purchase 2. Complete payment 3. Record time from payment confirmation to item appearing in inventory | G32: Item appears in inventory within 10 seconds of purchase confirmation; no manual refresh needed | H32: Critical | I32: Functional | J32: entitlement_granted | K32: Not Run
A33: TC-ENT-004 | B33: Entitlements | C33: Duplicate Handling | D33: Prevent duplicate purchase of one-time bundle | E33: Test account that has already purchased the one-time bundle | F33: 1. Navigate to store 2. Locate previously purchased one-time bundle 3. Attempt to purchase again | G33: Store prevents re-purchase; item greyed out or buy button disabled; clear 'already owned' message | H33: Critical | I33: Functional | K33: Fail
A34: TC-ENT-005 | B34: Entitlements | C34: Cross-Platform Sync | D34: Entitlement purchased on iOS visible on desktop client | E34: Test account linked across iOS and desktop; item purchased on iOS | F34: 1. Purchase item on iOS build 2. Log in to desktop game client with same account 3. Check inventory | G34: Item visible in desktop inventory without manual sync; no delay beyond reasonable login time | H34: High | I34: Integration | J34: entitlement_granted | K34: Fail
A35: TC-ENT-006 | B35: Entitlements | C35: Cross-Platform Sync | D35: Entitlement purchased on Android visible on desktop client | E35: Test account linked across Android and desktop; item purchased on Android | F35: 1. Purchase item on Android build 2. Log in to desktop client 3. Check inventory | G35: Item visible in desktop inventory; account state consistent across platforms | H35: High | I35: Integration | J35: entitlement_granted | K35: Pass
A36: Failure Scenarios
A37: TC-FAIL-001 | B37: Failure Scenarios | C37: Network | D37: Disconnect Wi-Fi mid-purchase | E37: Test device on Wi-Fi; purchase in progress | F37: 1. Begin purchase flow 2. Reach payment confirmation step 3. Disable Wi-Fi 4. Observe response 5. Reconnect and check account state | G37: System handles gracefully; no double charge; purchase either rolls back cleanly or completes on reconnect; account state consistent | H37: Critical | I37: Network | J37: purchase_failed | K37: Pass
A38: TC-FAIL-002 | B38: Failure Scenarios | C38: Network | D38: Timeout during payment processing | E38: Test account at payment card info screen | F38: 1. Enter card details 2. Leave on card entry screen for 30+ minutes 3. Attempt to confirm | G38: Session times out gracefully; clear timeout message; no charge made; player can retry | H38: High | I38: Network | J38: purchase_failed | K38: Pass
A39: TC-FAIL-003 | B39: Failure Scenarios | C39: Fulfilment | D39: Payment succeeds but entitlement fails to deliver | E39: Simulated entitlement failure (mocked via test environment) | F39: 1. Complete payment successfully 2. Simulate entitlement service failure 3. Observe player experience and backend logs | G39: Player shown error message; telemetry logs entitlement_failed; no item delivered; retry mechanism triggered or support contact offered | H39: Critical | I39: Integration | J39: payment_authorised, purchase_completed, entitlement_failed | K39: Pass
A40: TC-FAIL-004 | B40: Failure Scenarios | C40: UI | D40: UI does not reflect updated balance after purchase | E40: Test account purchases 1000+150 bonus currency | F40: 1. Note current balance 2. Purchase currency bundle 3. Observe UI immediately after receipt | G40: UI updates to correct balance without manual refresh; if UI shows 0 or old value, this is a failure | H40: High | I40: Functional | J40: purchase_completed | K40: Pass
A41: TC-FAIL-005 | B41: Failure Scenarios | C41: Retry | D41: Retry purchase immediately after failure | E41: Previous purchase attempt has failed (no charge) | F41: 1. Experience a failed purchase 2. Immediately attempt same purchase again without leaving store | G41: Retry is allowed; no cooldown preventing re-attempt; second attempt can succeed with valid details | H41: High | I41: Negative | J41: purchase_initiated, payment_authorised, purchase_completed | K41: Pass
...

Sheet Summary Dashboard
A1: Test Execution Summary
A2: Status counts update automatically when the Status column in the Test Cases sheet is updated.
A4: Module | B4: Total TCs | C4: Not Run | D4: In Progress | E4: Pass | F4: Fail | G4: Blocked | H4: Pass Rate
A5: Payment Methods | B5: 8 | C5: =COUNTIFS('Test Cases'!B:B,A5,'Test Cases'!K:K,"Not Run") -> 4 | D5: =COUNTIFS('Test Cases'!B:B,A5,'Test Cases'!K:K,"In Progress") -> 1 | E5: =COUNTIFS('Test Cases'!B:B,A5,'Test Cases'!K:K,"Pass") -> 1 | F5: =COUNTIFS('Test Cases'!B:B,A5,'Test Cases'!K:K,"Fail") -> 1 | G5: =COUNTIFS('Test Cases'!B:B,A5,'Test Cases'!K:K,"Blocked") -> 1 | H5: =IF(COUNTIF('Test Cases'!B:B,A5)>0,COUNTIFS('Test Cases'!B:B,A5,'Test Cases'!K:K,"Pass")/COUNTIF('Test Cases'!B:B,A5),"") -> 0.125
A6: Gifting | B6: 7 | C6: =COUNTIFS('Test Cases'!B:B,A6,'Test Cases'!K:K,"Not Run") -> 1 | D6: =COUNTIFS('Test Cases'!B:B,A6,'Test Cases'!K:K,"In Progress") -> 0 | E6: =COUNTIFS('Test Cases'!B:B,A6,'Test Cases'!K:K,"Pass") -> 5 | F6: =COUNTIFS('Test Cases'!B:B,A6,'Test Cases'!K:K,"Fail") -> 0 | G6: =COUNTIFS('Test Cases'!B:B,A6,'Test Cases'!K:K,"Blocked") -> 1 | H6: =IF(COUNTIF('Test Cases'!B:B,A6)>0,COUNTIFS('Test Cases'!B:B,A6,'Test Cases'!K:K,"Pass")/COUNTIF('Test Cases'!B:B,A6),"") -> 0.71428571
A7: Currency | B7: 6 | C7: =COUNTIFS('Test Cases'!B:B,A7,'Test Cases'!K:K,"Not Run") -> 0 | D7: =COUNTIFS('Test Cases'!B:B,A7,'Test Cases'!K:K,"In Progress") -> 1 | E7: =COUNTIFS('Test Cases'!B:B,A7,'Test Cases'!K:K,"Pass") -> 4 | F7: =COUNTIFS('Test Cases'!B:B,A7,'Test Cases'!K:K,"Fail") -> 1 | G7: =COUNTIFS('Test Cases'!B:B,A7,'Test Cases'!K:K,"Blocked") -> 0 | H7: =IF(COUNTIF('Test Cases'!B:B,A7)>0,COUNTIFS('Test Cases'!B:B,A7,'Test Cases'!K:K,"Pass")/COUNTIF('Test Cases'!B:B,A7),"") -> 0.66666667
A8: Entitlements | B8: 6 | C8: =COUNTIFS('Test Cases'!B:B,A8,'Test Cases'!K:K,"Not Run") -> 1 | D8: =COUNTIFS('Test Cases'!B:B,A8,'Test Cases'!K:K,"In Progress") -> 0 | E8: =COUNTIFS('Test Cases'!B:B,A8,'Test Cases'!K:K,"Pass") -> 1 | F8: =COUNTIFS('Test Cases'!B:B,A8,'Test Cases'!K:K,"Fail") -> 3 | G8: =COUNTIFS('Test Cases'!B:B,A8,'Test Cases'!K:K,"Blocked") -> 1 | H8: =IF(COUNTIF('Test Cases'!B:B,A8)>0,COUNTIFS('Test Cases'!B:B,A8,'Test Cases'!K:K,"Pass")/COUNTIF('Test Cases'!B:B,A8),"") -> 0.16666667
A9: Failure Scenarios | B9: 6 | C9: =COUNTIFS('Test Cases'!B:B,A9,'Test Cases'!K:K,"Not Run") -> 0 | D9: =COUNTIFS('Test Cases'!B:B,A9,'Test Cases'!K:K,"In Progress") -> 0 | E9: =COUNTIFS('Test Cases'!B:B,A9,'Test Cases'!K:K,"Pass") -> 5 | F9: =COUNTIFS('Test Cases'!B:B,A9,'Test Cases'!K:K,"Fail") -> 1 | G9: =COUNTIFS('Test Cases'!B:B,A9,'Test Cases'!K:K,"Blocked") -> 0 | H9: =IF(COUNTIF('Test Cases'!B:B,A9)>0,COUNTIFS('Test Cases'!B:B,A9,'Test Cases'!K:K,"Pass")/COUNTIF('Test Cases'!B:B,A9),"") -> 0.83333333
A10: Telemetry | B10: 11 | C10: =COUNTIFS('Test Cases'!B:B,A10,'Test Cases'!K:K,"Not Run") -> 0 | D10: =COUNTIFS('Test Cases'!B:B,A10,'Test Cases'!K:K,"In Progress") -> 1 | E10: =COUNTIFS('Test Cases'!B:B,A10,'Test Cases'!K:K,"Pass") -> 4 | F10: =COUNTIFS('Test Cases'!B:B,A10,'Test Cases'!K:K,"Fail") -> 2 | G10: =COUNTIFS('Test Cases'!B:B,A10,'Test Cases'!K:K,"Blocked") -> 4 | H10: =IF(COUNTIF('Test Cases'!B:B,A10)>0,COUNTIFS('Test Cases'!B:B,A10,'Test Cases'!K:K,"Pass")/COUNTIF('Test Cases'!B:B,A10),"") -> 0.36363636
A11: TOTAL | B11: 44 | C11: =COUNTIF('Test Cases'!K:K,"Not Run") -> 6 | D11: =COUNTIF('Test Cases'!K:K,"In Progress") -> 3 | E11: =COUNTIF('Test Cases'!K:K,"Pass") -> 20 | F11: =COUNTIF('Test Cases'!K:K,"Fail") -> 8 | G11: =COUNTIF('Test Cases'!K:K,"Blocked") -> 7 | H11: =IF(E11>0,E11/B11,"") -> 0.45454545

Sheet Defect Log
A1: Defect Log
A3: Defect ID | B3: Related TC | C3: Module | D3: Title / Summary | E3: Severity | F3: Steps to Reproduce | G3: Expected | H3: Actual | I3: Status | J3: JIRA Ref

Sheet Telemetry Validation
A1: Telemetry Event Validation Log
A3: Event Name | B3: Trigger Scenario | C3: Required Fields | D3: Fired? | E3: Payload Valid? | F3: Duplicate Check | G3: Timestamp | H3: Datadog Ref | I3: Notes
A4: purchase_initiated | B4: Player begins checkout | C4: player_id, session_id, item_id, timestamp, region, platform
A5: payment_authorised | B5: Payment successfully authenticated | C5: player_id, transaction_id, payment_method, amount, currency, timestamp
A6: payment_declined | B6: Payment rejected by provider | C6: player_id, transaction_id, decline_reason, timestamp
A7: purchase_completed | B7: Full purchase flow successful | C7: player_id, transaction_id, item_id, amount, timestamp
A8: purchase_failed | B8: Purchase unsuccessful (any reason) | C8: player_id, transaction_id, failure_reason, timestamp
A9: receipt_validated | B9: Receipt confirmed post-payment | C9: player_id, transaction_id, receipt_id, timestamp
A10: entitlement_granted | B10: Item delivered to player inventory | C10: player_id, item_id, transaction_id, delivery_time_ms, timestamp
A11: entitlement_failed | B11: Item failed to deliver post-payment | C11: player_id, item_id, transaction_id, failure_reason, timestamp
A12: entitlement_revoked | B12: Item removed from player inventory | C12: player_id, item_id, revocation_reason, revoked_by, timestamp
